Workbook
Name _Toc77749861: Sheet2!$D$1078
Name _Toc77749864: Sheet2!$D$1138
Name _Toc77749865: Sheet2!#REF!
Name tvpllink_fihxvisxtf_1: Sheet2!$D$70

Sheet Sheet2
B1: 4 | C1: x
A2: =ROUNDUP((ROW()-1)/5,0) -> 1 | B2: =IF(B1=4,0,B1+1) -> 0 | C2: =LEFT(D2,3) -> Câu | D2: Câu số 01: Phương pháp cấp cứu hồi sinh tổng hợp gồm mấy bước:
A3: =ROUNDUP((ROW()-1)/5,0) -> 1 | B3: =IF(B2=4,0,B2+1) -> 1 | C3: =LEFT(D3,3) -> A./ | D3: A./ 3 bước.
A4: =ROUNDUP((ROW()-1)/5,0) -> 1 | B4: =IF(B3=4,0,B3+1) -> 2 | C4: =LEFT(D4,3) -> B./ | D4: B./ 4 bước.
A5: =ROUNDUP((ROW()-1)/5,0) -> 1 | B5: =IF(B4=4,0,B4+1) -> 3 | C5: =LEFT(D5,3) -> C./ | D5: C./ 5 bước.
A6: =ROUNDUP((ROW()-1)/5,0) -> 1 | B6: =IF(B5=4,0,B5+1) -> 4 | C6: =LEFT(D6,3) -> D./ | D6: D./ 6 bước.
A7: =ROUNDUP((ROW()-1)/5,0) -> 2 | B7: =IF(B6=4,0,B6+1) -> 0 | C7: =LEFT(D7,3) -> Câu | D7: Câu số 02: Trình tự Phương pháp cấp cứu hồi sinh tổng hợp là: [Trong đó: (A) – Airway (Khôi phục hệ hô hấp); (B) – Breathing (Hô hấp nhân tạo); (C) – Circulation (Khôi phục hệ tuần hoàn); (D) – Danger (Loại trừ nguy hiểm); (R) – Response (Phản ứng)]
A8: =ROUNDUP((ROW()-1)/5,0) -> 2 | B8: =IF(B7=4,0,B7+1) -> 1 | C8: =LEFT(D8,3) -> A./ | D8: A./ DRCAB. Sau đó duy trì bước C rồi B theo nhịp 30/2 (30 lần ấn tim thì hô hấp nhân tạo 2 lần).
A9: =ROUNDUP((ROW()-1)/5,0) -> 2 | B9: =IF(B8=4,0,B8+1) -> 2 | C9: =LEFT(D9,3) -> B./ | D9: B./ DRCAB. Sau đó duy trì bước C rồi B theo nhịp 15/2 (15 lần ấn tim thì hô hấp nhân tạo 2 lần).
A10: =ROUNDUP((ROW()-1)/5,0) -> 2 | B10: =IF(B9=4,0,B9+1) -> 3 | C10: =LEFT(D10,3)
A11: =ROUNDUP((ROW()-1)/5,0) -> 2 | B11: =IF(B10=4,0,B10+1) -> 4 | C11: =LEFT(D11,3) -> D./ | D11: D./ DRABC. Sau đó duy trì bước C rồi B theo nhịp 15/2 (15 lần ấn tim thì hô hấp nhân tạo 2 lần).
A12: =ROUNDUP((ROW()-1)/5,0) -> 3 | B12: =IF(B11=4,0,B11+1) -> 0 | C12: =LEFT(D12,3) -> Câu | D12: Câu số 03: Tần số ấn nhịp tim trong Phương pháp cấp cứu hồi sinh tổng hợp là bao nhiêu?
A13: =ROUNDUP((ROW()-1)/5,0) -> 3 | B13: =IF(B12=4,0,B12+1) -> 1 | C13: =LEFT(D13,3) -> A./ | D13: A./ 70 đến 90 lần/phút.
A14: =ROUNDUP((ROW()-1)/5,0) -> 3 | B14: =IF(B13=4,0,B13+1) -> 2 | C14: =LEFT(D14,3) -> B./ | D14: B./ 80 đến 100 lần/phút.
A15: =ROUNDUP((ROW()-1)/5,0) -> 3 | B15: =IF(B14=4,0,B14+1) -> 3 | C15: =LEFT(D15,3) -> C./ | D15: C./ 90 đến 110 lần/phút.
A16: =ROUNDUP((ROW()-1)/5,0) -> 3 | B16: =IF(B15=4,0,B15+1) -> 4 | C16: =LEFT(D16,3) -> D./ | D16: D./ 100 đến 120 lần/phút.
A17: =ROUNDUP((ROW()-1)/5,0) -> 4 | B17: =IF(B16=4,0,B16+1) -> 0 | C17: =LEFT(D17,3) -> Câu | D17: Câu số 04: Động tác ấn tim ngoài lồng ngực trong Phương pháp cấp cứu hồi sinh tổng hợp có độ sâu bao nhiêu?
A18: =ROUNDUP((ROW()-1)/5,0) -> 4 | B18: =IF(B17=4,0,B17+1) -> 1 | C18: =LEFT(D18,3) -> A./ | D18: A./ Ấn sâu từ 3 đến 4 cm.
A19: =ROUNDUP((ROW()-1)/5,0) -> 4 | B19: =IF(B18=4,0,B18+1) -> 2 | C19: =LEFT(D19,3) -> B./ | D19: B./ Ấn sâu từ 4 đến 5 cm.
A20: =ROUNDUP((ROW()-1)/5,0) -> 4 | B20: =IF(B19=4,0,B19+1) -> 3 | C20: =LEFT(D20,3) -> C./ | D20: C./ Ấn sâu từ 5 đến 6 cm.
A21: =ROUNDUP((ROW()-1)/5,0) -> 4 | B21: =IF(B20=4,0,B20+1) -> 4 | C21: =LEFT(D21,3) -> D./ | D21: D./ Ấn sâu từ 6 đến 7 cm.
A22: =ROUNDUP((ROW()-1)/5,0) -> 5 | B22: =IF(B21=4,0,B21+1) -> 0 | C22: =LEFT(D22,3) -> Câu | D22: Câu số 05: Thời gian mỗi lần hô hấp trong Phương pháp cấp cứu hồi sinh tổng hợp là bao lâu?
... A277: =ROUNDUP((ROW()-1)/5,0) -> 56 | B277: =IF(B276=4,0,B276+1) -> 0 | C277: =LEFT(D277,3) -> Câu | D277: Câu số 56: Khi làm việc trên ĐDK hạ áp có điện hoặc tiếp xúc trực tiếp với phần có điện hạ áp thì phải thực hiện theo quy định như thế nào ?
A278: =ROUNDUP((ROW()-1)/5,0) -> 56 | B278: =IF(B277=4,0,B277+1) -> 1 | C278: =LEFT(D278,3)
A279: =ROUNDUP((ROW()-1)/5,0) -> 56 | B279: =IF(B278=4,0,B278+1) -> 2 | C279: =LEFT(D279,3) -> B./ | D279: B./ Người làm việc gần phần có điện hạ áp phải dùng các tấm cách điện để che, chắn.
A280: =ROUNDUP((ROW()-1)/5,0) -> 56 | B280: =IF(B279=4,0,B279+1) -> 3 | C280: =LEFT(D280,3) -> C./ | D280: C./ Gồm cả 02 đáp án A và B.
A281: =ROUNDUP((ROW()-1)/5,0) -> 56 | B281: =IF(B280=4,0,B280+1) -> 4 | C281: =LEFT(D281,3) -> D./ | D281: D./ Cả 02 đáp án A và B đều sai.
A282: =ROUNDUP((ROW()-1)/5,0) -> 57 | B282: =IF(B281=4,0,B281+1) -> 0 | C282: =LEFT(D282,3) -> Câu | D282: Câu số 57: Trong công tác thay chì trên cột phải thực hiện như thế nào ?
A283: =ROUNDUP((ROW()-1)/5,0) -> 57 | B283: =IF(B282=4,0,B282+1) -> 1 | C283: =LEFT(D283,3) -> A./ | D283: A./ Có 02 người.
A284: =ROUNDUP((ROW()-1)/5,0) -> 57 | B284: =IF(B283=4,0,B283+1) -> 2 | C284: =LEFT(D284,3) -> B./ | D284: B./ Trời khô ráo, không có giông, gió to, sấm sét.
A285: =ROUNDUP((ROW()-1)/5,0) -> 57 | B285: =IF(B284=4,0,B284+1) -> 3 | C285: =LEFT(D285,3) -> C./ | D285: C./ Quần áo người công nhân phải khô ráo, cột có chỗ đứng chắc chắn.
A286: =ROUNDUP((ROW()-1)/5,0) -> 57 | B286: =IF(B285=4,0,B285+1) -> 4 | C286: =LEFT(D286,3) -> D./ | D286: D./ Gồm cả 03 đáp án A, B và C.
A287: =ROUNDUP((ROW()-1)/5,0) -> 58 | B287: =IF(B286=4,0,B286+1) -> 0 | C287: =LEFT(D287,3) -> Câu | D287: Câu số 58: Nguyên tắc khi kiểm tra không còn điện bằng bút thử điện?
A288: =ROUNDUP((ROW()-1)/5,0) -> 58 | B288: =IF(B287=4,0,B287+1) -> 1 | C288: =LEFT(D288,3) -> A./ | D288: A./ Thử ở nơi không có điện trước, nơi có điện sau.
A289: =ROUNDUP((ROW()-1)/5,0) -> 58 | B289: =IF(B288=4,0,B288+1) -> 2 | C289: =LEFT(D289,3) -> B./ | D289: B./ Thử ở nơi có điện trước rồi mới thử nơi không còn điện.
A290: =ROUNDUP((ROW()-1)/5,0) -> 58 | B290: =IF(B289=4,0,B289+1) -> 3 | C290: =LEFT(D290,3) -> C./ | D290: C./ Nếu ở nơi công tác không có điện thì cho phép đem thử ở nơi khác trước lúc thử ở nơi công tác và phải bảo quản tốt bút thử điện khi chuyên chở.
... A439: =ROUNDUP((ROW()-1)/5,0) -> 88 | B439: =IF(B438=4,0,B438+1) -> 2 | C439: =LEFT(D439,3) -> B./ | D439: B./ Nếu làm việc trên đường dây một nguồn cấp không có nhánh rẽ, cho phép làm nối đất ở đầu đường dây có nguồn cấp đến, đầu còn lại phải mở thiết bị đóng cắt hoặc tháo lèo.
A440: =ROUNDUP((ROW()-1)/5,0) -> 88 | B440: =IF(B439=4,0,B439+1) -> 3 | C440: =LEFT(D440,3)
A441: =ROUNDUP((ROW()-1)/5,0) -> 88 | B441: =IF(B440=4,0,B440+1) -> 4 | C441: =LEFT(D441,3) -> D./ | D441: D./ Tất cả đều đúng.
A442: =ROUNDUP((ROW()-1)/5,0) -> 89 | B442: =IF(B441=4,0,B441+1) -> 0 | C442: =LEFT(D442,3) -> Câu | D442: Câu số 89: Khi làm việc trên đường dây hai nguồn cấp không có nhánh rẽ thì biện pháp đảm bảo an toàn là gì ?
...

Sheet Sheet3
C1: =ROW() -> 1 | D1: =COUNTIFS(Sheet2!A:A,Sheet3!C1) -> 5
A2: 1 | C2: =ROW() -> 2 | D2: =COUNTIFS(Sheet2!A:A,Sheet3!C2) -> 5
A3: 2 | C3: =ROW() -> 3 | D3: =COUNTIFS(Sheet2!A:A,Sheet3!C3) -> 5
A4: 3 | C4: =ROW() -> 4 | D4: =COUNTIFS(Sheet2!A:A,Sheet3!C4) -> 5
A5: 4 | C5: =ROW() -> 5 | D5: =COUNTIFS(Sheet2!A:A,Sheet3!C5) -> 5
A6: 5 | C6: =ROW() -> 6 | D6: =COUNTIFS(Sheet2!A:A,Sheet3!C6) -> 5
A7: 6 | C7: =ROW() -> 7 | D7: =COUNTIFS(Sheet2!A:A,Sheet3!C7) -> 5
A8: 7 | C8: =ROW() -> 8 | D8: =COUNTIFS(Sheet2!A:A,Sheet3!C8) -> 5
A9: 8 | C9: =ROW() -> 9 | D9: =COUNTIFS(Sheet2!A:A,Sheet3!C9) -> 5
A10: 9 | C10: =ROW() -> 10 | D10: =COUNTIFS(Sheet2!A:A,Sheet3!C10) -> 5
A11: 10 | C11: =ROW() -> 11 | D11: =COUNTIFS(Sheet2!A:A,Sheet3!C11) -> 5
A12: 11 | C12: =ROW() -> 12 | D12: =COUNTIFS(Sheet2!A:A,Sheet3!C12) -> 5
A13: 12 | C13: =ROW() -> 13 | D13: =COUNTIFS(Sheet2!A:A,Sheet3!C13) -> 5
... A325: 248 | C325: =ROW() -> 325 | D325: =COUNTIFS(Sheet2!A:A,Sheet3!C325) -> 0
C326: =ROW() -> 326 | D326: =COUNTIFS(Sheet2!A:A,Sheet3!C326) -> 0
C327: =ROW() -> 327 | D327: =COUNTIFS(Sheet2!A:A,Sheet3!C327) -> 0
C328: =ROW() -> 328 | D328: =COUNTIFS(Sheet2!A:A,Sheet3!C328) -> 0
C329: =ROW() -> 329 | D329: =COUNTIFS(Sheet2!A:A,Sheet3!C329) -> 0
C330: =ROW() -> 330 | D330: =COUNTIFS(Sheet2!A:A,Sheet3!C330) -> 0
C331: =ROW() -> 331 | D331: =COUNTIFS(Sheet2!A:A,Sheet3!C331) -> 0
C332: =ROW() -> 332 | D332: =COUNTIFS(Sheet2!A:A,Sheet3!C332) -> 0
C333: =ROW() -> 333 | D333: =COUNTIFS(Sheet2!A:A,Sheet3!C333) -> 0
C334: =ROW() -> 334 | D334: =COUNTIFS(Sheet2!A:A,Sheet3!C334) -> 0
C335: =ROW() -> 335 | D335: =COUNTIFS(Sheet2!A:A,Sheet3!C335) -> 0
C336: =ROW() -> 336 | D336: =COUNTIFS(Sheet2!A:A,Sheet3!C336) -> 0
C337: =ROW() -> 337 | D337: =COUNTIFS(Sheet2!A:A,Sheet3!C337) -> 0
... C420: =ROW() -> 420 | D420: =COUNTIFS(Sheet2!A:A,Sheet3!C420) -> 0
