Workbook

Sheet HuongDan
B1: BIỂU MẪU THU THẬP SỐ LIỆU THEO VĂN BẢN SỐ 5459/SCT-QLNL NGÀY 02/10/2026 CỦA SỞ CÔNG THƯƠNG
B2: Dùng nội bộ Công ty Điện lực Đồng Nai – các Điện lực, Phòng chủ trì điền và gửi Phòng Kinh doanh theo thời hạn tại công văn triển khai.
B4: CÁCH ĐIỀN
B5: 1. Chỉ nhập vào ô nền VÀNG. Ô nền xám nhạt (dòng "VD") là dòng ví dụ minh họa định dạng – XÓA nội dung dòng ví dụ trước khi gửi. Ô nền xám đậm là dòng tổng, tự tính bằng công thức.
B6: 2. Ghi tên Điện lực tại ô C3 của mỗi biểu. Thêm dòng bằng cách chèn dòng phía trên dòng "Tổng cộng" để công thức tổng tự mở rộng.
B7: 3. Mốc số liệu: đến hết 30/9/2026; điện năng năm 2025; 9 tháng 2026; 12 tháng từ 10/2025 đến 9/2026 (theo từng chỉ tiêu).
B8: 4. Tổng hợp theo đơn vị hành chính xã, phường hiện hành. Xã, phường do nhiều Điện lực cùng quản lý: ghi phần thuộc Điện lực mình và ghi chú rõ.
B9: 5. Biểu 01, 02, 03: chỉ số liệu tổng hợp, KHÔNG kèm thông tin cá nhân khách hàng.
B10: 6. Công suất ĐMTMN ghi theo kWp tấm quang điện; nếu chỉ có kW inverter thì ghi rõ tại cột Ghi chú.
B11: 7. Biểu 01: cột (10), (11) Sở Công Thương yêu cầu dạng "số hộ/công suất"; biểu nội bộ tách thành 2 cột để cộng tổng, Phòng Kinh doanh sẽ ghép khi gửi Sở. Cột (12a), (12b) là cột bổ sung nội bộ phục vụ Mục I.2.c.
B12: 8. Biểu 04: điện năng, tiền điện từng tháng nhập tại sheet Bieu04_12thang; cột (10), (12) của Biểu 04 tự cộng theo mã khách hàng. Cột (13a), (13b) bổ sung nội bộ phục vụ Mục II.2.
B13: 9. Biểu 03: kèm danh sách chi tiết TBA quá tải, quá áp tại sheet Bieu03_DS_TBA.

Sheet Bieu01
A1: Biểu 01. KHÁCH HÀNG SINH HOẠT VÀ HIỆN TRẠNG ĐMTMN HỘ GIA ĐÌNH THEO XÃ, PHƯỜNG
A2: (Số liệu đến hết ngày 30/9/2026 – theo Văn bản số 5459/SCT-QLNL)
A3: Điện lực:
A5: TT | B5: Xã, phường | C5: Tổng số hộ KH sinh hoạt (hộ) | D5: Số hộ dùng công tơ 01 pha | E5: Số hộ dùng công tơ 03 pha | F5: Điện năng sinh hoạt năm 2025 (kWh) | G5: Điện năng sinh hoạt 9 tháng 2026 (kWh) | H5: Số hộ đã lắp ĐMTMN (hộ) | I5: Tổng công suất ĐMTMN (kWp) | J5: (10a) Theo giá cố định trước 2021 – số hộ | K5: (10b) Theo giá cố định trước 2021 – kWp | L5: (11a) Có lưu trữ điện – số hộ | M5: (11b) Có lưu trữ điện – dung lượng (kWh) | N5: Số hộ có HĐ mua bán điện dư theo NĐ 58 | O5: (12a) Sản lượng điện dư theo NĐ 58 đã mua 9T/2026 (kWh) | P5: (12b) Số hộ thỏa thuận tỷ lệ > 50% | Q5: Ghi chú
A6: (1) | B6: (2) | C6: (3) | D6: (4) | E6: (5) | F6: (6) | G6: (7) | H6: (8) | I6: (9) | J6: (10) | K6: (11) | L6: (12) | M6: (13) | N6: (14) | O6: (15) | P6: (16) | Q6: (17)
A7: VD | B7: Phường X (ví dụ) | C7: =IF(COUNT(D7:E7)=0,"",D7+E7) -> 12500 | D7: 11800 | E7: 700 | F7: 38500000 | G7: 31200000 | H7: 210 | I7: 1260 | J7: 15 | K7: 90 | L7: 8 | M7: 80 | N7: 120 | O7: 95000 | P7: 6 | Q7: Ví dụ
A8: 2 | B8: Phường Bảo Vinh | C8: =IF(COUNT(D8:E8)=0,"",D8+E8) -> 12 | D8: 12 | F8: 37096 | G8: 31641
A9: 3 | B9: Phường Long Khánh | C9: =IF(COUNT(D9:E9)=0,"",D9+E9) -> 23 | D9: 23 | F9: 62826 | G9: 46325
A10: 4 | B10: Phường Hàng Gòn | C10: =IF(COUNT(D10:E10)=0,"",D10+E10) -> 25 | D10: 25 | F10: 57363 | G10: 45508
A11: 5 | B11: Xã Xuân Đông | C11: =IF(COUNT(D11:E11)=0,"",D11+E11) -> 7 | D11: 7 | F11: 18551 | G11: 18927
A12: 6 | B12: Xã Xuân Định | C12: =IF(COUNT(D12:E12)=0,"",D12+E12) -> 5671 | D12: 5644 | E12: 27 | F12: 15396829 | G12: 12375967 | H12: 45 | I12: 2696.285 | J12: 45 | K12: 2696.285
A13: 7 | B13: Xã Xuân Phú | C13: =IF(COUNT(D13:E13)=0,"",D13+E13) -> 5515 | D13: 5500 | E13: 15 | F13: 13836560 | G13: 11093680 | H13: 34 | I13: 18599.815 | J13: 34 | K13: 18599.815
A14: 8 | B14: Xã Xuân Hòa | C14: =IF(COUNT(D14:E14)=0,"",D14+E14) -> 18879 | D14: 18839 | E14: 40 | F14: 48385905 | G14: 38535811 | H14: 86 | I14: 51950.945 | J14: 86 | K14: 51950.945
A15: 9 | B15: Xã Xuân Thành | C15: =IF(COUNT(D15:E15)=0,"",D15+E15) -> 4757 | D15: 4753 | E15: 4 | F15: 11917343 | G15: 9672175 | H15: 40 | I15: 32104 | J15: 40 | K15: 32104
A16: 10 | B16: Xã Xuân Bắc | C16: =IF(COUNT(D16:E16)=0,"",D16+E16) -> 3305 | D16: 3300 | E16: 5 | F16: 8478408 | G16: 6839961 | H16: 13 | I16: 9778.43 | J16: 13 | K16: 9778.43
A17: 11 | B17: Phường Xuân Lộc | C17: =IF(COUNT(D17:E17)=0,"",D17+E17) -> 25143 | D17: 25094 | E17: 49 | F17: 72924295 | G17: 58276090 | H17: 94 | I17: 18206.2 | J17: 94 | K17: 18206.2
A18: 12
A19: 13
A20: 14 | C20: =IF(COUNT(D20:E20)=0,"",D20+E20)
A21: 15 | C21: =IF(COUNT(D21:E21)=0,"",D21+E21)
A22: 16 | C22: =IF(COUNT(D22:E22)=0,"",D22+E22)
A23: 17 | C23: =IF(COUNT(D23:E23)=0,"",D23+E23)
A24: 18 | C24: =IF(COUNT(D24:E24)=0,"",D24+E24)
A25: 19 | C25: =IF(COUNT(D25:E25)=0,"",D25+E25)
A26: 20 | C26: =IF(COUNT(D26:E26)=0,"",D26+E26)
A27: 21 | C27: =IF(COUNT(D27:E27)=0,"",D27+E27)
A28: 22 | C28: =IF(COUNT(D28:E28)=0,"",D28+E28)
A29: 23 | C29: =IF(COUNT(D29:E29)=0,"",D29+E29)
A30: 24 | C30: =IF(COUNT(D30:E30)=0,"",D30+E30)
A31: 25 | C31: =IF(COUNT(D31:E31)=0,"",D31+E31)
... A37: 31 | C37: =IF(COUNT(D37:E37)=0,"",D37+E37)
B38: Tổng cộng | C38: =SUM(C8:C37) -> 63337 | D38: =SUM(D8:D37) -> 63197 | E38: =SUM(E8:E37) -> 140 | F38: =SUM(F8:F37) -> 171115176 | G38: =SUM(G8:G37) -> 136936085 | H38: =SUM(H8:H37) -> 312 | I38: =SUM(I8:I37) -> 133335.67 | J38: =SUM(J8:J37) -> 312 | ... P38: =SUM(P8:P37) -> 0
A40: Cột (3) tự tính = (4) + (5). Cột (9) ghi theo công suất lắp đặt đã khai báo/nghiệm thu; trường hợp chỉ có công suất inverter (kW) thì ghi rõ tại Ghi chú.

Sheet Bieu02
A1: Biểu 02. PHÂN BỐ HỘ KHÁCH HÀNG SINH HOẠT THEO MỨC ĐIỆN NĂNG TIÊU THỤ
A2: (Bình quân tháng từ tháng 10/2025 đến tháng 9/2026)
A3: Điện lực:
A5: TT | B5: Mức điện năng tiêu thụ bình quân tháng (kWh/tháng) | C5: Số hộ (hộ) | D5: Tỷ lệ (%) | E5: Điện năng 12 tháng (kWh) | F5: Số hộ đã lắp ĐMTMN (hộ) | G5: Công suất ĐMTMN (kWp) | H5: Ghi chú
A6: (1) | B6: (2) | C6: (3) | D6: (4) | E6: (5) | F6: (6) | G6: (7) | H6: (8)
A7: 1 | B7: Từ 0 - 50 | C7: 5881 | D7: =IF(SUM($C$7:$C$12)=0,"",C7/SUM($C$7:$C$12)) -> 0.092852519 | E7: 1185288
A8: 2 | B8: Từ 51 - 100 | C8: 21867 | D8: =IF(SUM($C$7:$C$12)=0,"",C8/SUM($C$7:$C$12)) -> 0.34524843 | E8: 39973680
A9: 3 | B9: Từ 101 - 200 | C9: 15768 | D9: =IF(SUM($C$7:$C$12)=0,"",C9/SUM($C$7:$C$12)) -> 0.24895401 | E9: 46264368
A10: 4 | B10: Từ 201 - 300 | C10: 7258 | D10: =IF(SUM($C$7:$C$12)=0,"",C10/SUM($C$7:$C$12)) -> 0.11459337 | E10: 29889996
A11: 5 | B11: Từ 301 - 400 | C11: 6888 | D11: =IF(SUM($C$7:$C$12)=0,"",C11/SUM($C$7:$C$12)) -> 0.1087516 | E11: 50357544
A12: 6 | B12: Từ 401 trở lên | C12: 5675 | D12: =IF(SUM($C$7:$C$12)=0,"",C12/SUM($C$7:$C$12)) -> 0.089600076 | E12: 5345496
B13: Tổng cộng | C13: =SUM(C7:C12) -> 63337 | D13: =IF(SUM(C7:C12)=0,"",SUM(D7:D12)) -> 1 | E13: =SUM(E7:E12) -> 173016372 | F13: =SUM(F7:F12) -> 0 | G13: =SUM(G7:G12) -> 0
A15: Các mức tiêu thụ theo bậc biểu giá bán lẻ điện sinh hoạt hiện hành; nếu biểu giá áp dụng có cơ cấu bậc khác, điều chỉnh và ghi chú.
A16: Biểu này do Phòng Kinh doanh trích xuất CMIS cho toàn Công ty; Điện lực không phải điền nếu không được yêu cầu.

Sheet Bieu03
A1: Biểu 03. KHẢ NĂNG TIẾP NHẬN ĐMTMN CỦA LƯỚI ĐIỆN PHÂN PHỐI THEO XÃ, PHƯỜNG
A2: (Số liệu đến hết ngày 30/9/2026)
A3: Điện lực:
A5: TT | B5: Xã, phường | C5: Số TBA phân phối công cộng (trạm) | D5: Tổng dung lượng TBA (kVA) | E5: Tổng công suất ĐMTMN đấu nối hạ áp (kWp) | F5: Số TBA vận hành bình thường/ nguy cơ quá tải/ quá áp / phát ngược | G5: Số trường hợp đã phản hồi tạm dừng (khoản 5 Điều 15 NĐ 58) | H5: Khả năng tiếp nhận thêm 2027–2030 (kWp, ước tính) | I5: Kế hoạch cải tạo, nâng cấp lưới | J5: Ghi chú
A6: (1) | B6: (2) | C6: (3) | D6: (4) | E6: (5) | F6: (6) | G6: (7) | H6: (8) | I6: (9) | J6: (10)
A7: VD | B7: Phường X (ví dụ) | C7: 85 | D7: 32500 | E7: 1260 | F7: 3 | G7: 2 | H7: 800 | I7: Cải tạo, nâng công suất 02 TBA năm 2027 | J7: Ví dụ
A8: 2 | B8: Xã Xuân Định | C8: =COUNTIFS(Bieu03A_DS_TBA!B:B,Bieu03!B8) -> 102 | D8: =SUMIFS(Bieu03A_DS_TBA!E:E,Bieu03A_DS_TBA!B:B,Bieu03!B8) -> 20195 | E8: =SUMIFS(Bieu03A_DS_TBA!G:G,Bieu03A_DS_TBA!B:B,Bieu03!B8) -> 1151.005 | F8: 102 | H8: 2000 | I8: Cải tạo, nâng cấp từ 1 pha lên 3 pha 1 TBA năm 2027, 12 TBA năm 2028, 7 TBA năm 2029, 1 TBA năm 2030
A9: 3 | B9: Xã Xuân Phú | C9: =COUNTIFS(Bieu03A_DS_TBA!B:B,Bieu03!B9) -> 102 | D9: =SUMIFS(Bieu03A_DS_TBA!E:E,Bieu03A_DS_TBA!B:B,Bieu03!B9) -> 15875 | E9: =SUMIFS(Bieu03A_DS_TBA!G:G,Bieu03A_DS_TBA!B:B,Bieu03!B9) -> 193.265 | F9: 102 | H9: 1500 | I9: Cải tạo, nâng cấp từ 1 pha lên 3 pha 9 TBA năm 2027, 2 TBA năm 2028, 8 TBA năm 2029, TBA năm 2030
A10: 4 | B10: Xã Xuân Hòa | C10: =COUNTIFS(Bieu03A_DS_TBA!B:B,Bieu03!B10) -> 167 | D10: =SUMIFS(Bieu03A_DS_TBA!E:E,Bieu03A_DS_TBA!B:B,Bieu03!B10) -> 30750 | E10: =SUMIFS(Bieu03A_DS_TBA!G:G,Bieu03A_DS_TBA!B:B,Bieu03!B10) -> 798.975 | F10: 167 | H10: 3000 | I10: Cải tạo, nâng cấp từ 1 pha lên 3 pha 4 TBA năm 2027, 2 TBA năm 2028, 4 TBA năm 2029, 2 TBA năm 2030
A11: 5 | B11: Xã Xuân Thành | C11: =COUNTIFS(Bieu03A_DS_TBA!B:B,Bieu03!B11) -> 83 | D11: =SUMIFS(Bieu03A_DS_TBA!E:E,Bieu03A_DS_TBA!B:B,Bieu03!B11) -> 10365 | E11: =SUMIFS(Bieu03A_DS_TBA!G:G,Bieu03A_DS_TBA!B:B,Bieu03!B11) -> 114.48 | F11: 83 | H11: 1000 | I11: Cải tạo, nâng cấp từ 1 pha lên 3 pha 3 TBA năm 2027, 1 TBA năm 2028, 4 TBA năm 2030
A12: 6 | B12: Xã Xuân Bắc | C12: =COUNTIFS(Bieu03A_DS_TBA!B:B,Bieu03!B12) -> 103 | D12: =SUMIFS(Bieu03A_DS_TBA!E:E,Bieu03A_DS_TBA!B:B,Bieu03!B12) -> 13845 | E12: =SUMIFS(Bieu03A_DS_TBA!G:G,Bieu03A_DS_TBA!B:B,Bieu03!B12) -> 24.37 | F12: 103 | H12: 1000 | I12: Cải tạo, nâng cấp từ 1 pha lên 3 pha 4 TBA năm 2027, 4 TBA năm 2028, 4 TBA năm 2029, 6 TBA năm 2030
A13: 7 | B13: Phường Xuân Lộc | C13: =COUNTIFS(Bieu03A_DS_TBA!B:B,Bieu03!B13) -> 282 | D13: =SUMIFS(Bieu03A_DS_TBA!E:E,Bieu03A_DS_TBA!B:B,Bieu03!B13) -> 48990 | E13: =SUMIFS(Bieu03A_DS_TBA!G:G,Bieu03A_DS_TBA!B:B,Bieu03!B13) -> 1382.81 | F13: 282 | H13: 4000 | I13: Cải tạo, nâng cấp từ 1 pha lên 3 pha 4 TBA năm 2027, 17 TBA năm 2028, 6 TBA năm 2029, 10 TBA năm 2030
A14: 8
A15: 9
A16: 10
A17: 11
A18: 12
A19: 13
A20: 14
A21: 15
A22: 16
A23: 17
A24: 18
A25: 19
... A37: 31
B38: Tổng cộng | C38: =SUM(C8:C37) -> 839 | D38: =SUM(D8:D37) -> 140020 | E38: =SUM(E8:E37) -> 3664.905 | F38: =SUM(F8:F37) -> 839 | G38: =SUM(G8:G37) -> 0 | H38: =SUM(H8:H37) -> 12500
A40: Cột (6): kê chi tiết từng trạm tại sheet Bieu03_DS_TBA (tên trạm, địa điểm, dung lượng, mức mang tải, công suất ĐMTMN đã đấu nối).

Sheet Bieu03A_DS_TBA
A1: DANH SÁCH TBA CÓ KHẢ NĂNG TIẾP NHẬN ĐMTMN CỦA LƯỚI ĐIỆN PHÂN PHỐI THEO XÃ, PHƯỜNG (kèm Biểu 03)
A2: (Số liệu đến hết ngày 30/9/2026)
A3: Điện lực:
A5: TT | B5: Xã, phường | C5: Tên trạm | D5: Địa điểm | E5: Dung lượng (kVA) | F5: Mức mang tải cực đại (%) | G5: Công suất ĐMTMN đã đấu nối (kWp) | H5: Hiện tượng (bình thường/ quá tải / quá áp/ phát ngược) | I5: Ghi chú
A6: (1) | B6: (2) | C6: (3) | D6: (4) | E6: (5) | F6: (6) | G6: (7) | H6: (8) | I6: (9)
A7: VD | B7: Phường X (ví dụ) | C7: TBA KP3-4 | D7: Tổ 5, khu phố 3 | E7: 250 | F7: 1.12 | G7: 95 | H7: phát ngược | I7: Ví dụ
A8: 2 | B8: Xã Xuân Hòa | C8: ẤP 4 XUÂN HƯNG | D8: Ấp 4, Xã Xuân Hòa, Thành phố Đồng Nai | E8: 200 | F8: 0.72 | G8: 0 | H8: Bình thường
A9: 3 | B9: Xã Xuân Hòa | C9: ẤP 4 XUÂN HƯNG A | D9: Ấp 4, Xã Xuân Hòa, Thành phố Đồng Nai | E9: 100 | F9: 0.69 | G9: 0 | H9: Bình thường
A10: 4 | B10: Xã Xuân Hòa | C10: ẤP 4 XUÂN HƯNG B | D10: Ấp 4, Xã Xuân Hòa, Thành phố Đồng Nai | E10: 100 | F10: 0.69 | G10: 0 | H10: Bình thường
A11: 5 | B11: Phường Xuân Lộc | C11: BẢO CHÁNH 1 | D11: Suối Cát 2, Phường Xuân Lộc, Thành phố Đồng Nai | E11: 150 | F11: 0.71 | G11: 3.12 | H11: Bình thường
A12: 6 | B12: Phường Xuân Lộc | C12: BẢO CHÁNH 1A | D12: Suối Cát 2, Phường Xuân Lộc, Thành phố Đồng Nai | E12: 112.5 | F12: 0.73 | G12: 0 | H12: Bình thường
A13: 7 | B13: Phường Xuân Lộc | C13: BẢO CHÁNH 1C | D13: khu phố Suối Cát 2, Phường Xuân Lộc, Thành phố Đồng Nai | E13: 150 | F13: 0.75 | G13: 0 | H13: Bình thường
A14: 8 | B14: Phường Xuân Lộc | C14: BẢO CHÁNH 2 | D14: Thọ Bình, Phường Xuân Lộc, Thành phố Đồng Nai | E14: 225 | F14: 0.58 | G14: 55.88 | H14: Bình thường
A15: 9 | B15: Phường Xuân Lộc | C15: BẢO CHÁNH 2A | D15: Thọ Bình, Phường Xuân Lộc, Thành phố Đồng Nai | E15: 225 | F15: 0.52 | G15: 5.28 | H15: Bình thường
A16: 10 | B16: Phường Xuân Lộc | C16: BẢO CHÁNH 3 | D16: Thọ Bình, Phường Xuân Lộc, Thành phố Đồng Nai | E16: 100 | F16: 0.48 | G16: 26.83 | H16: Bình thường
A17: 11 | B17: Phường Xuân Lộc | C17: BẢO CHÁNH 3A | D17: Thọ Bình, Phường Xuân Lộc, Thành phố Đồng Nai | E17: 150 | F17: 0.47 | G17: 3.28 | H17: Bình thường
A18: 12 | B18: Phường Xuân Lộc | C18: BẢO CHÁNH 3B | D18: Thọ Bình, Phường Xuân Lộc, Thành phố Đồng Nai | E18: 75 | F18: 0.72 | G18: 0 | H18: Bình thường
A19: 13 | B19: Phường Xuân Lộc | C19: BẢO CHÁNH 3C | D19: khu phố Thọ Bình, Phường Xuân Lộc, Thành phố Đồng Nai | E19: 50 | F19: 0.45 | G19: 0 | H19: Bình thường
... A57: 51 | B57: Phường Xuân Lộc | C57: BÀU SEN 1 | D57: khu phố Trung Nghĩa, Phường Xuân Lộc, Thành phố Đồng Nai | E57: 150 | F57: 0.54 | G57: 0 | H57: Bình thường
B58: Phường Xuân Lộc | C58: BÀU SEN 1A | D58: khu phố Trung Nghĩa, Phường Xuân Lộc, Thành phố Đồng Nai | E58: 150 | F58: 0.73 | G58: 0 | H58: Bình thường
B59: Phường Xuân Lộc | C59: BÀU SEN 2 | D59: khu phố Bầu Sen, Phường Xuân Lộc, Thành phố Đồng Nai | E59: 250 | F59: 0.5 | G59: 0 | H59: Bình thường
B60: Phường Xuân Lộc | C60: BÀU SEN 3 | D60: khu phố Trung Hiếu, Phường Xuân Lộc, Thành phố Đồng Nai | E60: 150 | F60: 0.47 | G60: 0 | H60: Bình thường
B61: Phường Xuân Lộc | C61: BÀU SEN 3A | D61: khu phố Trung Hiếu, Phường Xuân Lộc, Thành phố Đồng Nai | E61: 75 | F61: 0.51 | G61: 0 | H61: Bình thường
B62: Phường Xuân Lộc | C62: BÀU SEN 4 | D62: khu phố Trung Hiếu, Phường Xuân Lộc, Thành phố Đồng Nai | E62: 75 | F62: 0.46 | G62: 0 | H62: Bình thường
B63: Phường Xuân Lộc | C63: BÀU SEN 5 | D63: khu phố Trung Hiếu, Phường Xuân Lộc, Thành phố Đồng Nai | E63: 100 | F63: 0.75 | G63: 0 | H63: Bình thường
B64: Phường Xuân Lộc | C64: BÀU SEN 6 | D64: Khu phố Bàu Sen, Phường Xuân Lộc, Thành phố Đồng Nai | E64: 150 | F64: 0.73 | G64: 0 | H64: Bình thường
B65: Phường Xuân Lộc | C65: BÀU SEN 6A | D65: Khu phố Bàu Sen, Phường Xuân Lộc, Thành phố Đồng Nai | E65: 50 | F65: 0.54 | G65: 0 | H65: Bình thường
B66: Phường Xuân Lộc | C66: BÀU SEN 7 | D66: Khu phố Bàu Sen, Phường Xuân Lộc, Thành phố Đồng Nai | E66: 100 | F66: 0.69 | G66: 0 | H66: Bình thường
B67: Xã Xuân Thành | C67: BÀU SÌNH 1 | D67: ấp Phượng Vỹ, Xã Xuân Thành, Thành phố Đồng Nai | E67: 150 | F67: 0.71 | G67: 12.76 | H67: Bình thường
B68: Xã Xuân Thành | C68: BÀU SÌNH 1A | D68: ấp Cây Da, Xã Xuân Thành, Thành phố Đồng Nai | E68: 150 | F68: 0.54 | G68: 0 | H68: Bình thường
B69: Xã Xuân Thành | C69: BÀU SÌNH 1B | D69: ấp Phượng Vỹ, Xã Xuân Thành, Thành phố Đồng Nai | E69: 50 | F69: 0.68 | G69: 0 | H69: Bình thường
... B846: Phường Xuân Lộc | C846: XUÂN TRƯỜNG 2A | D846: khu phố Trung Nghĩa, Phường Xuân Lộc, Thành phố Đồng Nai | E846: 160 | F846: 0.63 | G846: 0 | H846: Bình thường

Sheet Bieu04
A1: Biểu 04. DANH SÁCH KHÁCH HÀNG KHỐI HÀNH CHÍNH SỰ NGHIỆP (CƠ QUAN, CÔNG SỞ, TRƯỜNG HỌC, BỆNH VIỆN)
A2: (Số liệu 12 tháng từ tháng 10/2025 đến tháng 9/2026)
A3: Điện lực: | C3: Xuân Lộc
A5: TT | B5: Mã khách hàng | C5: Tên khách hàng | D5: Địa chỉ (xã, phường) | E5: Nhóm giá (1/2) | F5: Cơ quan NN, ĐVSN công lập (Có/Không) | G5: Cấp điện áp đấu nối | H5: Loại công tơ, hệ số nhân | I5: Pmax theo khoản 3 Điều 11 NĐ 58 (kW) | J5: Điện năng 12 tháng (kWh) | K5: Tỷ trọng điện năng 06h–18h (%) | L5: Tiền điện 12 tháng (đồng) | M5: ĐMTMN hiện có (kWp) / lưu trữ (kWh) | N5: (13a) Thời điểm đưa ĐMTMN vào vận hành | O5: (13b) Có bán điện dư (Có/Không) | P5: Ghi chú
A6: (1) | B6: (2) | C6: (3) | D6: (4) | E6: (5) | F6: (6) | G6: (7) | H6: (8) | I6: (9) | J6: (10) | K6: (11) | L6: (12) | M6: (13) | N6: (14) | O6: (15) | P6: (16)
A7: 1 | B7: PK05000076520 | C7: Ban Quản Lý dự án khu vực 07 | D7: Phường Xuân Lộc | E7: 2 | F7: Có | G7: Hạ áp | H7: Điện tử 1 pha, HSN 1 | I7: 18 | J7: =IF(B7="","",SUMIF(Bieu04A_12thang!$B:$B,B7,Bieu04A_12thang!$O:$O)) -> 18405 | L7: =IF(B7="","",SUMIF(Bieu04A_12thang!$B:$B,B7,Bieu04A_12thang!$AB:$AB)) -> 40969530
A8: 2 | B8: PK05000101726 | C8: Bảo hiểm Xã hội cơ sở Xuân Lộc | D8: Phường Xuân Lộc | E8: 2 | F8: Có | G8: Trung áp | H8: Điện tử 1 pha, HSN 1 | I8: 127 | J8: =IF(B8="","",SUMIF(Bieu04A_12thang!$B:$B,B8,Bieu04A_12thang!$O:$O)) -> 29556 | L8: =IF(B8="","",SUMIF(Bieu04A_12thang!$B:$B,B8,Bieu04A_12thang!$AB:$AB)) -> 65791656
A9: 3 | B9: PK05000002937 | C9: Công an phường Xuân Lộc | D9: Phường Xuân Lộc | E9: 2 | F9: Có | G9: Trung áp | H9: Điện tử 1 pha, HSN 1 | I9: 127 | J9: =IF(B9="","",SUMIF(Bieu04A_12thang!$B:$B,B9,Bieu04A_12thang!$O:$O)) -> 81437 | L9: =IF(B9="","",SUMIF(Bieu04A_12thang!$B:$B,B9,Bieu04A_12thang!$AB:$AB)) -> 181278762
A10: 4 | B10: PK05000002938 | C10: Công an phường Xuân Lộc | D10: Phường Xuân Lộc | E10: 2 | F10: Có | G10: Trung áp | H10: Điện tử 1 pha, HSN 1 | I10: 127 | J10: =IF(B10="","",SUMIF(Bieu04A_12thang!$B:$B,B10,Bieu04A_12thang!$O:$O)) -> 44392 | L10: =IF(B10="","",SUMIF(Bieu04A_12thang!$B:$B,B10,Bieu04A_12thang!$AB:$AB)) -> 98816592
A11: 5 | B11: PK05000002939 | C11: Công an phường Xuân Lộc | D11: Phường Xuân Lộc | E11: 2 | F11: Có | G11: Trung áp | H11: Điện tử 1 pha, HSN 1 | I11: 127 | J11: =IF(B11="","",SUMIF(Bieu04A_12thang!$B:$B,B11,Bieu04A_12thang!$O:$O)) -> 29085 | L11: =IF(B11="","",SUMIF(Bieu04A_12thang!$B:$B,B11,Bieu04A_12thang!$AB:$AB)) -> 64743210
A12: 6 | B12: PK05000095448 | C12: Công an phường Xuân Lộc | D12: Phường Xuân Lộc | E12: 2 | F12: Có | G12: Hạ áp | H12: Điện tử 1 pha, HSN 1 | I12: 18 | J12: =IF(B12="","",SUMIF(Bieu04A_12thang!$B:$B,B12,Bieu04A_12thang!$O:$O)) -> 11788 | L12: =IF(B12="","",SUMIF(Bieu04A_12thang!$B:$B,B12,Bieu04A_12thang!$AB:$AB)) -> 26240088
A13: 7 | B13: PK05000066209 | C13: Công an thành phố Đồng Nai | D13: Phường Xuân Lộc | E13: 2 | F13: Có | G13: Hạ áp | H13: Điện tử 1 pha, HSN 1 | I13: 10 | J13: =IF(B13="","",SUMIF(Bieu04A_12thang!$B:$B,B13,Bieu04A_12thang!$O:$O)) -> 7061 | L13: =IF(B13="","",SUMIF(Bieu04A_12thang!$B:$B,B13,Bieu04A_12thang!$AB:$AB)) -> 15717786
A14: 8 | B14: PK05000089246 | C14: Công An thành phố Đồng Nai | D14: Phường Xuân Lộc | E14: 2 | F14: Có | G14: Hạ áp | H14: Điện tử 1 pha, HSN 1 | I14: 10 | J14: =IF(B14="","",SUMIF(Bieu04A_12thang!$B:$B,B14,Bieu04A_12thang!$O:$O)) -> 10249 | L14: =IF(B14="","",SUMIF(Bieu04A_12thang!$B:$B,B14,Bieu04A_12thang!$AB:$AB)) -> 22814274
A15: 9 | B15: PK05000110443 | C15: Công An thành phố Đồng Nai | D15: Phường Xuân Lộc | E15: 2 | F15: Có | G15: Trung áp | H15: Điện tử 1 pha, HSN 1 | I15: 127 | J15: =IF(B15="","",SUMIF(Bieu04A_12thang!$B:$B,B15,Bieu04A_12thang!$O:$O)) -> 56975 | L15: =IF(B15="","",SUMIF(Bieu04A_12thang!$B:$B,B15,Bieu04A_12thang!$AB:$AB)) -> 126826350
A16: 10 | B16: PK05000111708 | C16: Công An thành phố Đồng Nai | D16: Phường Xuân Lộc | E16: 2 | F16: Có | G16: Hạ áp | H16: Điện tử 1 pha, HSN 1 | I16: 10 | J16: =IF(B16="","",SUMIF(Bieu04A_12thang!$B:$B,B16,Bieu04A_12thang!$O:$O)) -> 705 | L16: =IF(B16="","",SUMIF(Bieu04A_12thang!$B:$B,B16,Bieu04A_12thang!$AB:$AB)) -> 1569330
A17: 11 | B17: PK05000111713 | C17: Công An thành phố Đồng Nai | D17: Phường Xuân Lộc | E17: 2 | F17: Có | G17: Hạ áp | H17: Điện tử 1 pha, HSN 1 | I17: 10 | J17: =IF(B17="","",SUMIF(Bieu04A_12thang!$B:$B,B17,Bieu04A_12thang!$O:$O)) -> 630 | L17: =IF(B17="","",SUMIF(Bieu04A_12thang!$B:$B,B17,Bieu04A_12thang!$AB:$AB)) -> 1402380
A18: 12 | B18: PK05000111715 | C18: Công An thành phố Đồng Nai | D18: Phường Xuân Lộc | E18: 2 | F18: Có | G18: Hạ áp | H18: Điện tử 1 pha, HSN 1 | I18: 10 | J18: =IF(B18="","",SUMIF(Bieu04A_12thang!$B:$B,B18,Bieu04A_12thang!$O:$O)) -> 753 | L18: =IF(B18="","",SUMIF(Bieu04A_12thang!$B:$B,B18,Bieu04A_12thang!$AB:$AB)) -> 1676178
... A108: 102 | B108: PK05000048721 | C108: Trung tâm ngoại ngữ Đông Nam | D108: Phường Xuân Lộc | E108: 2 | F108: Không | G108: Hạ áp | H108: Điện tử 1 pha, HSN 1 | I108: 10 | J108: =IF(B108="","",SUMIF(Bieu04A_12thang!$B:$B,B108,Bieu04A_12thang!$O:$O)) -> 2714 | L108: =IF(B108="","",SUMIF(Bieu04A_12thang!$B:$B,B108,Bieu04A_12thang!$AB:$AB)) -> 6041364
A109: 103 | B109: PK05000003001 | C109: Trung tâm phát triển quỹ đất Chi nhánh Xuân Lộc | D109: Phường Xuân Lộc | E109: 2 | F109: Có | G109: Hạ áp | H109: Điện tử 1 pha, HSN 1 | I109: 18 | J109: =IF(B109="","",SUMIF(Bieu04A_12thang!$B:$B,B109,Bieu04A_12thang!$O:$O)) -> 16523 | L109: =IF(B109="","",SUMIF(Bieu04A_12thang!$B:$B,B109,Bieu04A_12thang!$AB:$AB)) -> 36780198 | M109: 0 / 0 | P109: Ví dụ
A110: 104 | B110: PK05000002981 | C110: Trung tâm phục vụ hành chính công phường Xuân Lộc | D110: Phường Xuân Lộc | E110: 2 | F110: Có | G110: Hạ áp | H110: Điện tử 1 pha, HSN 1 | I110: 18 | J110: =IF(B110="","",SUMIF(Bieu04A_12thang!$B:$B,B110,Bieu04A_12thang!$O:$O)) -> 68254 | L110: =IF(B110="","",SUMIF(Bieu04A_12thang!$B:$B,B110,Bieu04A_12thang!$AB:$AB)) -> 151933404
A111: 105 | B111: PK05000057818 | C111: Trung tâm Y tế khu vực Xuân Lộc | D111: Phường Xuân Lộc | E111: 1 | F111: Có | G111: Trung áp | H111: Điện tử 1 pha, HSN 1 | I111: 127 | J111: =IF(B111="","",SUMIF(Bieu04A_12thang!$B:$B,B111,Bieu04A_12thang!$O:$O)) -> 14181 | L111: =IF(B111="","",SUMIF(Bieu04A_12thang!$B:$B,B111,Bieu04A_12thang!$AB:$AB)) -> 29383032
A112: 106 | B112: PK05000066133 | C112: Trung tâm Y tế khu vực Xuân Lộc | D112: Phường Xuân Lộc | E112: 1 | F112: Có | G112: Trung áp | H112: Điện tử 1 pha, HSN 1 | I112: 127 | J112: =IF(B112="","",SUMIF(Bieu04A_12thang!$B:$B,B112,Bieu04A_12thang!$O:$O)) -> 666451 | L112: =IF(B112="","",SUMIF(Bieu04A_12thang!$B:$B,B112,Bieu04A_12thang!$AB:$AB)) -> 1380886472
A113: 107 | B113: PK05000105823 | C113: Trường TH - THCS Trần Phú | D113: Phường Xuân Lộc | E113: 1 | F113: Có | G113: Trung áp | H113: Điện tử 1 pha, HSN 1 | I113: 127 | J113: =IF(B113="","",SUMIF(Bieu04A_12thang!$B:$B,B113,Bieu04A_12thang!$O:$O)) -> 40690 | L113: =IF(B113="","",SUMIF(Bieu04A_12thang!$B:$B,B113,Bieu04A_12thang!$AB:$AB)) -> 84309680
A114: 108 | B114: PK05000077331 | C114: Trường Mầm Non Hồng Ân | D114: Phường Xuân Lộc | E114: 1 | F114: Có | G114: Hạ áp | H114: Điện tử 1 pha, HSN 1 | I114: 18 | J114: =IF(B114="","",SUMIF(Bieu04A_12thang!$B:$B,B114,Bieu04A_12thang!$O:$O)) -> 18772 | L114: =IF(B114="","",SUMIF(Bieu04A_12thang!$B:$B,B114,Bieu04A_12thang!$AB:$AB)) -> 38895584
A115: 109 | B115: PK05000051910 | C115: Trường Mầm Non Tư Thục Hướng Dương | D115: Phường Xuân Lộc | E115: 1 | F115: Không | G115: Hạ áp | H115: Điện tử 1 pha, HSN 1 | I115: 18 | J115: =IF(B115="","",SUMIF(Bieu04A_12thang!$B:$B,B115,Bieu04A_12thang!$O:$O)) -> 20378 | L115: =IF(B115="","",SUMIF(Bieu04A_12thang!$B:$B,B115,Bieu04A_12thang!$AB:$AB)) -> 42223216
A116: 110 | B116: PK05000070041 | C116: Trường mầm non Trảng Táo | D116: Phường Xuân Lộc | E116: 1 | F116: Có | G116: Hạ áp | H116: Điện tử 1 pha, HSN 1 | I116: 10 | J116: =IF(B116="","",SUMIF(Bieu04A_12thang!$B:$B,B116,Bieu04A_12thang!$O:$O)) -> 389 | L116: =IF(B116="","",SUMIF(Bieu04A_12thang!$B:$B,B116,Bieu04A_12thang!$AB:$AB)) -> 806008
A117: 111 | B117: PK05000006297 | C117: Trường mầm non Xuân Hiệp | D117: Phường Xuân Lộc | E117: 1 | F117: Có | G117: Hạ áp | H117: Điện tử 1 pha, HSN 1 | I117: 10 | J117: =IF(B117="","",SUMIF(Bieu04A_12thang!$B:$B,B117,Bieu04A_12thang!$O:$O)) -> 1450 | L117: =IF(B117="","",SUMIF(Bieu04A_12thang!$B:$B,B117,Bieu04A_12thang!$AB:$AB)) -> 3004400
A118: 112 | B118: PK05000080995 | C118: Trường mầm non Xuân Hiệp | D118: Phường Xuân Lộc | E118: 1 | F118: Có | G118: Trung áp | H118: Điện tử 1 pha, HSN 1 | I118: 127 | J118: =IF(B118="","",SUMIF(Bieu04A_12thang!$B:$B,B118,Bieu04A_12thang!$O:$O)) -> 20169 | L118: =IF(B118="","",SUMIF(Bieu04A_12thang!$B:$B,B118,Bieu04A_12thang!$AB:$AB)) -> 41790168
A119: 113 | B119: PK05000002936 | C119: Trường Mầm non Xuân Hiệp | D119: Phường Xuân Lộc | E119: 1 | F119: Có | G119: Hạ áp | H119: Điện tử 1 pha, HSN 1 | I119: 10 | J119: =IF(B119="","",SUMIF(Bieu04A_12thang!$B:$B,B119,Bieu04A_12thang!$O:$O)) -> 1473 | L119: =IF(B119="","",SUMIF(Bieu04A_12thang!$B:$B,B119,Bieu04A_12thang!$AB:$AB)) -> 3052056
A120: 114 | B120: PK05000040842 | C120: Trường Mầm Non Xuân Hiệp | D120: Phường Xuân Lộc | E120: 1 | F120: Có | G120: Hạ áp | H120: Điện tử 1 pha, HSN 1 | I120: 18 | J120: =IF(B120="","",SUMIF(Bieu04A_12thang!$B:$B,B120,Bieu04A_12thang!$O:$O)) -> 16442 | L120: =IF(B120="","",SUMIF(Bieu04A_12thang!$B:$B,B120,Bieu04A_12thang!$AB:$AB)) -> 34067824
A121: 115 | B121: PK05000081466 | C121: Trường mầm non Xuân Hiệp | D121: Phường Xuân Lộc | E121: 1 | F121: Có | G121: Hạ áp | H121: Điện tử 1 pha, HSN 1 | I121: 10 | J121: =IF(B121="","",SUMIF(Bieu04A_12thang!$B:$B,B121,Bieu04A_12thang!$O:$O)) -> 4047 | L121: =IF(B121="","",SUMIF(Bieu04A_12thang!$B:$B,B121,Bieu04A_12thang!$AB:$AB)) -> 8385384
... A248: 242 | B248: PK05000087327 | C248: Văn phòng HĐND và UBND Xã Xuân Định | D248: Xã Xuân Định | E248: 2 | F248: Có | G248: Trung áp | H248: Điện tử 1 pha, HSN 1 | I248: 127 | J248: =IF(B248="","",SUMIF(Bieu04A_12thang!$B:$B,B248,Bieu04A_12thang!$O:$O)) -> 67342 | L248: =IF(B248="","",SUMIF(Bieu04A_12thang!$B:$B,B248,Bieu04A_12thang!$AB:$AB)) -> 149903292
A249: 243 | B249: PK05000094112 | C249: Trung tâm Dịch vụ Tổng hợp xã Xuân Định | D249: xã Xuân Định | E249: 2 | F249: Có | G249: Hạ áp | H249: Điện tử 1 pha, HSN 1 | I249: 18 | J249: =IF(B249="","",SUMIF(Bieu04A_12thang!$B:$B,B249,Bieu04A_12thang!$O:$O)) -> 20091 | L249: =IF(B249="","",SUMIF(Bieu04A_12thang!$B:$B,B249,Bieu04A_12thang!$AB:$AB)) -> 44722566 | M249: 31.5 | N249: 43965 | O249: Có
A250: 244 | B250: PK05000079867 | C250: Ban chỉ huy Quân sự xã Xuân Hòa | D250: Xã Xuân Hòa | E250: 2 | F250: Có | G250: Hạ áp | H250: Điện tử 1 pha, HSN 1 | I250: 10 | J250: =IF(B250="","",SUMIF(Bieu04A_12thang!$B:$B,B250,Bieu04A_12thang!$O:$O)) -> 4996 | L250: =IF(B250="","",SUMIF(Bieu04A_12thang!$B:$B,B250,Bieu04A_12thang!$AB:$AB)) -> 11121096
A251: 245 | B251: PK05000111741 | C251: Công An thành phố Đồng Nai | D251: Xã Xuân Hòa | E251: 2 | F251: Có | G251: Hạ áp | H251: Điện tử 1 pha, HSN 1 | I251: 10 | J251: =IF(B251="","",SUMIF(Bieu04A_12thang!$B:$B,B251,Bieu04A_12thang!$O:$O)) -> 737 | L251: =IF(B251="","",SUMIF(Bieu04A_12thang!$B:$B,B251,Bieu04A_12thang!$AB:$AB)) -> 1640562
A252: 246 | B252: PK05000111746 | C252: Công An thành phố Đồng Nai | D252: Xã Xuân Hòa | E252: 2 | F252: Có | G252: Hạ áp | H252: Điện tử 1 pha, HSN 1 | I252: 10 | J252: =IF(B252="","",SUMIF(Bieu04A_12thang!$B:$B,B252,Bieu04A_12thang!$O:$O)) -> 722 | L252: =IF(B252="","",SUMIF(Bieu04A_12thang!$B:$B,B252,Bieu04A_12thang!$AB:$AB)) -> 1607172
A253: 247 | B253: PK05000111758 | C253: Công An thành phố Đồng Nai | D253: Xã Xuân Hòa | E253: 2 | F253: Có | G253: Hạ áp | H253: Điện tử 1 pha, HSN 1 | I253: 10 | J253: =IF(B253="","",SUMIF(Bieu04A_12thang!$B:$B,B253,Bieu04A_12thang!$O:$O)) -> 636 | L253: =IF(B253="","",SUMIF(Bieu04A_12thang!$B:$B,B253,Bieu04A_12thang!$AB:$AB)) -> 1415736
A254: 248 | B254: PK05000111763 | C254: Công An thành phố Đồng Nai | D254: Xã Xuân Hòa | E254: 2 | F254: Có | G254: Hạ áp | H254: Điện tử 1 pha, HSN 1 | I254: 10 | J254: =IF(B254="","",SUMIF(Bieu04A_12thang!$B:$B,B254,Bieu04A_12thang!$O:$O)) -> 109 | L254: =IF(B254="","",SUMIF(Bieu04A_12thang!$B:$B,B254,Bieu04A_12thang!$AB:$AB)) -> 242634
A255: 249 | B255: PK05000111764 | C255: Công An thành phố Đồng Nai | D255: Xã Xuân Hòa | E255: 2 | F255: Có | G255: Hạ áp | H255: Điện tử 1 pha, HSN 1 | I255: 10 | J255: =IF(B255="","",SUMIF(Bieu04A_12thang!$B:$B,B255,Bieu04A_12thang!$O:$O)) -> 214 | L255: =IF(B255="","",SUMIF(Bieu04A_12thang!$B:$B,B255,Bieu04A_12thang!$AB:$AB)) -> 476364
A256: 250 | B256: PK05000111782 | C256: Công An thành phố Đồng Nai | D256: Xã Xuân Hòa | E256: 2 | F256: Có | G256: Hạ áp | H256: Điện tử 1 pha, HSN 1 | I256: 10 | J256: =IF(B256="","",SUMIF(Bieu04A_12thang!$B:$B,B256,Bieu04A_12thang!$O:$O)) -> 633 | L256: =IF(B256="","",SUMIF(Bieu04A_12thang!$B:$B,B256,Bieu04A_12thang!$AB:$AB)) -> 1409058
...

Sheet Bieu04A_12thang
A1: ĐIỆN NĂNG, TIỀN ĐIỆN TỪNG THÁNG CỦA KHÁCH HÀNG TẠI BIỂU 04
A2: (Từ tháng 10/2025 đến tháng 9/2026)
A3: Điện lực:
A5: TT | B5: Mã khách hàng | C5: ĐN 10/2025 (kWh) | D5: ĐN 11/2025 (kWh) | E5: ĐN 12/2025 (kWh) | F5: ĐN 01/2026 (kWh) | G5: ĐN 02/2026 (kWh) | H5: ĐN 03/2026 (kWh) | I5: ĐN 04/2026 (kWh) | J5: ĐN 05/2026 (kWh) | K5: ĐN 06/2026 (kWh) | L5: ĐN 07/2026 (kWh) | M5: ĐN 08/2026 (kWh) | N5: ĐN 09/2026 (kWh) | O5: Tổng ĐN 12 tháng (kWh) | P5: Tiền điện 10/2025 (đồng) | Q5: Tiền điện 11/2025 (đồng) | R5: Tiền điện 12/2025 (đồng) | S5: Tiền điện 01/2026 (đồng) | T5: Tiền điện 02/2026 (đồng) | U5: Tiền điện 03/2026 (đồng) | V5: Tiền điện 04/2026 (đồng) | W5: Tiền điện 05/2026 (đồng) | X5: Tiền điện 06/2026 (đồng) | Y5: Tiền điện 07/2026 (đồng) | Z5: Tiền điện 08/2026 (đồng) | AA5: Tiền điện 09/2026 (đồng) | AB5: Tổng tiền điện 12 tháng (đồng)
A6: (1) | B6: (2) | C6: (3) | D6: (4) | E6: (5) | F6: (6) | G6: (7) | H6: (8) | I6: (9) | J6: (10) | K6: (11) | L6: (12) | M6: (13) | N6: (14) | O6: (15) | P6: (16) | Q6: (17) | R6: (18) | S6: (19) | T6: (20) | U6: (21) | V6: (22) | W6: (23) | X6: (24) | Y6: (25) | Z6: (26) | AA6: (27) | AB6: (28)
A7: VD | B7: PB0X000012345 | C7: 4200 | D7: 4300 | E7: 3900 | F7: 3100 | G7: 3800 | H7: 4600 | I7: 5200 | J7: 5300 | K7: 4100 | L7: 3900 | M7: 4400 | N7: 4500 | O7: =IF(B7="","",SUM(C7:N7)) -> 51300 | P7: 11130000 | Q7: 11395000 | R7: 10335000 | S7: 8215000 | T7: 10070000 | U7: 12190000 | V7: 13780000 | W7: 14045000 | X7: 10865000 | Y7: 10335000 | Z7: 11660000 | AA7: 11925000 | AB7: =IF(B7="","",SUM(P7:AA7)) -> 135945000
A8: 2 | B8: PK05000001630 | C8: 2556 | D8: 2140 | E8: 2229 | F8: 1939 | G8: 1439 | H8: 2800 | I8: 2955 | J8: 3028 | K8: 2250 | L8: 2720 | M8: 3023 | N8: 2569 | O8: =IF(B8="","",SUM(C8:N8)) -> 29648 | P8: 5546460 | Q8: 4605656 | R8: 4807956 | S8: 4148288 | T8: 3034688 | U8: 6112536 | V8: 6469784 | W8: 6636308 | X8: 4856580 | Y8: 5931508 | Z8: 6624560 | AA8: 5585324 | AB8: =IF(B8="","",SUM(P8:AA8)) -> 64359648
A9: 3 | B9: PK05000002928 | C9: 1016 | D9: 874 | E9: 1111 | F9: 935 | G9: 776 | H9: 1148 | I9: 1127 | J9: 997 | K9: 646 | L9: 690 | M9: 599 | N9: 1151 | O9: =IF(B9="","",SUM(C9:N9)) -> 11070 | P9: 2261616 | Q9: 1945524 | R9: 2473086 | S9: 2081310 | T9: 1727376 | U9: 2555448 | V9: 2508702 | W9: 2219322 | X9: 1437996 | Y9: 1535940 | Z9: 1333374 | AA9: 2562126 | AB9: =IF(B9="","",SUM(P9:AA9)) -> 24641820
A10: 4 | B10: PK05000002936 | C10: 173 | D10: 190 | E10: 161 | F10: 143 | G10: 82 | H10: 154 | I10: 158 | J10: 149 | K10: 13 | L10: 9 | M10: 77 | N10: 164 | O10: =IF(B10="","",SUM(C10:N10)) -> 1473 | P10: 358456 | Q10: 393680 | R10: 333592 | S10: 296296 | T10: 169904 | U10: 319088 | V10: 327376 | W10: 308728 | X10: 26936 | Y10: 18648 | Z10: 159544 | AA10: 339808 | AB10: =IF(B10="","",SUM(P10:AA10)) -> 3052056
A11: 5 | B11: PK05000002937 | C11: 4432 | D11: 5129 | E11: 5337 | F11: 5083 | G11: 5433 | H11: 7537 | I11: 8603 | J11: 9098 | K11: 8755 | L11: 8726 | M11: 7457 | N11: 5847 | O11: =IF(B11="","",SUM(C11:N11)) -> 81437 | P11: 9865632 | Q11: 11417154 | R11: 11880162 | S11: 11314758 | T11: 12093858 | U11: 16777362 | V11: 19150278 | W11: 20252148 | X11: 19488630 | Y11: 19424076 | Z11: 16599282 | AA11: 13015422 | AB11: =IF(B11="","",SUM(P11:AA11)) -> 181278762
A12: 6 | B12: PK05000002938 | C12: 3462 | D12: 2605 | E12: 3280 | F12: 2074 | G12: 2413 | H12: 3137 | I12: 5101 | J12: 5951 | K12: 5736 | L12: 4114 | M12: 3651 | N12: 2868 | O12: =IF(B12="","",SUM(C12:N12)) -> 44392 | P12: 7706412 | Q12: 5798730 | R12: 7301280 | S12: 4616724 | T12: 5371338 | U12: 6982962 | V12: 11354826 | W12: 13246926 | X12: 12768336 | Y12: 9157764 | Z12: 8127126 | AA12: 6384168 | AB12: =IF(B12="","",SUM(P12:AA12)) -> 98816592
A13: 7 | B13: PK05000002939 | C13: 2212 | D13: 2039 | E13: 2096 | F13: 1475 | G13: 1680 | H13: 2544 | I13: 2925 | J13: 3270 | K13: 2949 | L13: 3151 | M13: 2675 | N13: 2069 | O13: =IF(B13="","",SUM(C13:N13)) -> 29085 | P13: 4923912 | Q13: 4538814 | R13: 4665696 | S13: 3283350 | T13: 3739680 | U13: 5662944 | V13: 6511050 | W13: 7279020 | X13: 6564474 | Y13: 7014126 | Z13: 5954550 | AA13: 4605594 | AB13: =IF(B13="","",SUM(P13:AA13)) -> 64743210
A14: 8 | B14: PK05000002940 | C14: 148 | D14: 144 | E14: 106 | F14: 86 | G14: 51 | H14: 111 | I14: 165 | J14: 320 | K14: 280 | L14: 279 | M14: 269 | N14: 238 | O14: =IF(B14="","",SUM(C14:N14)) -> 2197 | P14: 329448 | Q14: 320544 | R14: 235956 | S14: 191436 | T14: 113526 | U14: 247086 | V14: 367290 | W14: 712320 | X14: 623280 | Y14: 621054 | Z14: 598794 | AA14: 529788 | AB14: =IF(B14="","",SUM(P14:AA14)) -> 4890522
A15: 9 | B15: PK05000002952 | C15: 598 | D15: 581 | E15: 570 | F15: 551 | G15: 543 | H15: 633 | I15: 705 | J15: 824 | K15: 766 | L15: 818 | M15: 771 | N15: 737 | O15: =IF(B15="","",SUM(C15:N15)) -> 8097 | P15: 1239056 | Q15: 1203832 | R15: 1181040 | S15: 1141672 | T15: 1125096 | U15: 1311576 | V15: 1460760 | W15: 1707328 | X15: 1587152 | Y15: 1694896 | Z15: 1597512 | AA15: 1527064 | AB15: =IF(B15="","",SUM(P15:AA15)) -> 16776984
A16: 10 | B16: PK05000002953 | C16: 19 | D16: 58 | E16: 28 | F16: 14 | G16: 17 | H16: 84 | I16: 24 | J16: 23 | K16: 23 | L16: 24 | M16: 18 | N16: 18 | O16: =IF(B16="","",SUM(C16:N16)) -> 350 | P16: 42294 | Q16: 129108 | R16: 62328 | S16: 31164 | T16: 37842 | U16: 186984 | V16: 53424 | W16: 51198 | X16: 51198 | Y16: 53424 | Z16: 40068 | AA16: 40068 | AB16: =IF(B16="","",SUM(P16:AA16)) -> 779100
A17: 11 | B17: PK05000002956 | C17: 296 | D17: 283 | E17: 337 | F17: 291 | G17: 264 | H17: 347 | I17: 361 | J17: 357 | K17: 302 | L17: 103 | O17: =IF(B17="","",SUM(C17:N17)) -> 2941 | P17: 658896 | Q17: 629958 | R17: 750162 | S17: 647766 | T17: 587664 | U17: 772422 | V17: 803586 | W17: 794682 | X17: 672252 | Y17: 229278 | AB17: =IF(B17="","",SUM(P17:AA17)) -> 6546666
A18: 12 | B18: PK05000002968 | O18: =IF(B18="","",SUM(C18:N18)) -> 0 | AB18: =IF(B18="","",SUM(P18:AA18)) -> 0
A19: 13 | B19: PK05000002969 | C19: 7810 | D19: 7584 | E19: 7971 | F19: 5870 | G19: 7966 | H19: 10493 | I19: 11675 | J19: 11525 | K19: 9392 | L19: 9098 | M19: 9643 | N19: 8694 | O19: =IF(B19="","",SUM(C19:N19)) -> 107721 | P19: 17385060 | Q19: 16881984 | R19: 17743446 | S19: 13066620 | T19: 17732316 | U19: 23357418 | V19: 25988550 | W19: 25654650 | X19: 20906592 | Y19: 20252148 | Z19: 21465318 | AA19: 19352844 | AB19: =IF(B19="","",SUM(P19:AA19)) -> 239786946
A20: 14 | B20: PK05000002970 | C20: 2927 | D20: 2475 | E20: 2612 | F20: 2051 | G20: 1636 | H20: 3023 | I20: 3851 | J20: 3525 | K20: 3600 | L20: 3519 | M20: 3040 | N20: 2600 | O20: =IF(B20="","",SUM(C20:N20)) -> 34859 | P20: 6515502 | Q20: 5509350 | R20: 5814312 | S20: 4565526 | T20: 3641736 | U20: 6729198 | V20: 8572326 | W20: 7846650 | X20: 8013600 | Y20: 7833294 | Z20: 6767040 | AA20: 5787600 | AB20: =IF(B20="","",SUM(P20:AA20)) -> 77596134
A21: 15 | B21: PK05000002971 | C21: 140 | D21: 14 | E21: 11 | F21: 13 | G21: 16 | H21: 19 | I21: 14 | J21: 13 | K21: 23 | L21: 22 | M21: 294 | N21: 543 | O21: =IF(B21="","",SUM(C21:N21)) -> 1122 | P21: 311640 | Q21: 31164 | R21: 24486 | S21: 28938 | T21: 35616 | U21: 42294 | V21: 31164 | W21: 28938 | X21: 51198 | Y21: 48972 | Z21: 654444 | AA21: 1208718 | AB21: =IF(B21="","",SUM(P21:AA21)) -> 2497572
A22: 16 | B22: PK05000002973 | C22: 1240 | D22: 998 | E22: 1057 | F22: 315 | I22: 235 | J22: 546 | K22: 541 | L22: 522 | M22: 654 | N22: 606 | O22: =IF(B22="","",SUM(C22:N22)) -> 6714 | P22: 2760240 | Q22: 2221548 | R22: 2352882 | S22: 701190 | V22: 523110 | W22: 1215396 | X22: 1204266 | Y22: 1161972 | Z22: 1455804 | AA22: 1348956 | AB22: =IF(B22="","",SUM(P22:AA22)) -> 14945364
A23: 17 | B23: PK05000002974 | C23: 1218 | D23: 724 | E23: 658 | F23: 431 | G23: 398 | H23: 956 | I23: 1295 | J23: 1635 | K23: 1583 | L23: 1465 | M23: 1905 | N23: 823 | O23: =IF(B23="","",SUM(C23:N23)) -> 13091 | P23: 2711268 | Q23: 1611624 | R23: 1464708 | S23: 959406 | T23: 885948 | U23: 2128056 | V23: 2882670 | W23: 3639510 | X23: 3523758 | Y23: 3261090 | Z23: 4240530 | AA23: 1831998 | AB23: =IF(B23="","",SUM(P23:AA23)) -> 29140566
A24: 18 | B24: PK05000002975 | C24: 1222 | D24: 964 | E24: 999 | F24: 857 | G24: 646 | H24: 1243 | I24: 1405 | J24: 1306 | K24: 551 | L24: 444 | M24: 547 | N24: 1025 | O24: =IF(B24="","",SUM(C24:N24)) -> 11209 | P24: 2531984 | Q24: 1997408 | R24: 2069928 | S24: 1775704 | T24: 1338512 | U24: 2575496 | V24: 2911160 | W24: 2706032 | X24: 1141672 | Y24: 919968 | Z24: 1133384 | AA24: 2123800 | AB24: =IF(B24="","",SUM(P24:AA24)) -> 23225048
A25: 19 | B25: PK05000002980 | C25: 5917 | D25: 5152 | E25: 5666 | F25: 5366 | G25: 6953 | H25: 8577 | I25: 12167 | J25: 9502 | K25: 7301 | L25: 6783 | M25: 6275 | N25: 5254 | O25: =IF(B25="","",SUM(C25:N25)) -> 84913 | P25: 13171242 | Q25: 11468352 | R25: 12612516 | S25: 11944716 | T25: 15477378 | U25: 19092402 | V25: 27083742 | W25: 21151452 | X25: 16252026 | Y25: 15098958 | Z25: 13968150 | AA25: 11695404 | AB25: =IF(B25="","",SUM(P25:AA25)) -> 189016338
A26: 20 | B26: PK05000002981 | C26: 5907 | D26: 4969 | E26: 5043 | F26: 4209 | G26: 4459 | H26: 6299 | I26: 6773 | J26: 6711 | K26: 5945 | L26: 6020 | M26: 5992 | N26: 5927 | O26: =IF(B26="","",SUM(C26:N26)) -> 68254 | P26: 13148982 | Q26: 11060994 | R26: 11225718 | S26: 9369234 | T26: 9925734 | U26: 14021574 | V26: 15076698 | W26: 14938686 | X26: 13233570 | Y26: 13400520 | Z26: 13338192 | AA26: 13193502 | AB26: =IF(B26="","",SUM(P26:AA26)) -> 151933404
A27: 21 | B27: PK05000002983 | C27: 739 | D27: 909 | E27: 1030 | F27: 732 | G27: 900 | H27: 1427 | I27: 1622 | J27: 1551 | K27: 1234 | L27: 1437 | M27: 1376 | N27: 1111 | O27: =IF(B27="","",SUM(C27:N27)) -> 14068 | P27: 1645014 | Q27: 2023434 | R27: 2292780 | S27: 1629432 | T27: 2003400 | U27: 3176502 | V27: 3610572 | W27: 3452526 | X27: 2746884 | Y27: 3198762 | Z27: 3062976 | AA27: 2473086 | AB27: =IF(B27="","",SUM(P27:AA27)) -> 31315368
A28: 22 | B28: PK05000002991 | C28: 5965 | D28: 5547 | E28: 5401 | F28: 4844 | G28: 3177 | H28: 5463 | I28: 5775 | J28: 5709 | K28: 2595 | L28: 3139 | M28: 4787 | N28: 5881 | O28: =IF(B28="","",SUM(C28:N28)) -> 58283 | P28: 12359480 | Q28: 11493384 | R28: 11190872 | S28: 10036768 | T28: 6582744 | U28: 11319336 | V28: 11965800 | W28: 11829048 | X28: 5376840 | Y28: 6504008 | Z28: 9918664 | AA28: 12185432 | AB28: =IF(B28="","",SUM(P28:AA28)) -> 120762376
A29: 23 | B29: PK05000002994 | C29: 7031 | D29: 5883 | E29: 6086 | F29: 5745 | G29: 3428 | H29: 5924 | I29: 6668 | J29: 4896 | K29: 2437 | L29: 1776 | M29: 1933 | N29: 5599 | O29: =IF(B29="","",SUM(C29:N29)) -> 57406 | P29: 14568232 | Q29: 12189576 | R29: 12610192 | S29: 11903640 | T29: 7102816 | U29: 12274528 | V29: 13816096 | W29: 10144512 | X29: 5049464 | Y29: 3679872 | Z29: 4005176 | AA29: 11601128 | AB29: =IF(B29="","",SUM(P29:AA29)) -> 118945232
A30: 24 | B30: PK05000002997 | C30: 3988 | D30: 3443 | E30: 3786 | F30: 3300 | G30: 2346 | H30: 3892 | I30: 3446 | J30: 2887 | K30: 991 | L30: 830 | M30: 1236 | N30: 3652 | O30: =IF(B30="","",SUM(C30:N30)) -> 33797 | P30: 8263136 | Q30: 7133896 | R30: 7844592 | S30: 6837600 | T30: 4860912 | U30: 8064224 | V30: 7140112 | W30: 5981864 | X30: 2053352 | Y30: 1719760 | Z30: 2560992 | AA30: 7566944 | AB30: =IF(B30="","",SUM(P30:AA30)) -> 70027384
A31: 25 | B31: PK05000002998 | C31: 864 | D31: 1001 | E31: 812 | F31: 728 | G31: 719 | H31: 1163 | I31: 1199 | J31: 1226 | K31: 1195 | L31: 1107 | M31: 1248 | N31: 872 | O31: =IF(B31="","",SUM(C31:N31)) -> 12134 | P31: 1923264 | Q31: 2228226 | R31: 1807512 | S31: 1620528 | T31: 1600494 | U31: 2588838 | V31: 2668974 | W31: 2729076 | X31: 2660070 | Y31: 2464182 | Z31: 2778048 | AA31: 1941072 | AB31: =IF(B31="","",SUM(P31:AA31)) -> 27010284
A32: 26 | B32: PK05000003001 | C32: 791 | D32: 1020 | E32: 933 | F32: 833 | G32: 815 | H32: 990 | I32: 1376 | J32: 2394 | K32: 1703 | L32: 1615 | M32: 1993 | N32: 2060 | O32: =IF(B32="","",SUM(C32:N32)) -> 16523 | P32: 1760766 | Q32: 2270520 | R32: 2076858 | S32: 1854258 | T32: 1814190 | U32: 2203740 | V32: 3062976 | W32: 5329044 | X32: 3790878 | Y32: 3594990 | Z32: 4436418 | AA32: 4585560 | AB32: =IF(B32="","",SUM(P32:AA32)) -> 36780198
A33: 27 | B33: PK05000003006 | C33: 634 | D33: 932 | E33: 738 | F33: 707 | G33: 645 | H33: 866 | I33: 1027 | J33: 900 | K33: 805 | L33: 751 | M33: 800 | N33: 731 | O33: =IF(B33="","",SUM(C33:N33)) -> 9536 | P33: 1313648 | Q33: 1931104 | R33: 1529136 | S33: 1464904 | T33: 1336440 | U33: 1794352 | V33: 2127944 | W33: 1864800 | X33: 1667960 | Y33: 1556072 | Z33: 1657600 | AA33: 1514632 | AB33: =IF(B33="","",SUM(P33:AA33)) -> 19758592
A34: 28 | B34: PK05000003007 | C34: 1175 | D34: 1634 | E34: 1291 | F34: 1334 | G34: 1449 | H34: 1443 | I34: 1398 | J34: 1490 | K34: 1407 | L34: 1327 | M34: 1401 | N34: 1742 | O34: =IF(B34="","",SUM(C34:N34)) -> 17091 | P34: 2615550 | Q34: 3637284 | R34: 2873766 | S34: 2969484 | T34: 3225474 | U34: 3212118 | V34: 3111948 | W34: 3316740 | X34: 3131982 | Y34: 2953902 | Z34: 3118626 | AA34: 3877692 | AB34: =IF(B34="","",SUM(P34:AA34)) -> 38044566
A35: 29 | B35: PK05000003012 | C35: 12 | D35: 18 | E35: 18 | F35: 9 | G35: 7 | H35: 59 | J35: 6 | K35: 9 | L35: 17 | M35: 17 | N35: 18 | O35: =IF(B35="","",SUM(C35:N35)) -> 190 | P35: 26712 | Q35: 40068 | R35: 40068 | S35: 20034 | T35: 15582 | U35: 131334 | W35: 13356 | X35: 20034 | Y35: 37842 | Z35: 37842 | AA35: 40068 | AB35: =IF(B35="","",SUM(P35:AA35)) -> 422940
A36: 30 | B36: PK05000003804 | C36: 163 | D36: 252 | E36: 128 | F36: 106 | G36: 143 | H36: 211 | I36: 197 | J36: 373 | K36: 173 | L36: 178 | M36: 216 | N36: 290 | O36: =IF(B36="","",SUM(C36:N36)) -> 2430 | P36: 362838 | Q36: 560952 | R36: 284928 | S36: 235956 | T36: 318318 | U36: 469686 | V36: 438522 | W36: 830298 | X36: 385098 | Y36: 396228 | Z36: 480816 | AA36: 645540 | AB36: =IF(B36="","",SUM(P36:AA36)) -> 5409180
A37: 31 | B37: PK05000006281 | C37: 229 | D37: 138 | E37: 139 | F37: 147 | G37: 103 | H37: 149 | I37: 175 | J37: 95 | K37: 34 | L37: 54 | M37: 20 | N37: 91 | O37: =IF(B37="","",SUM(C37:N37)) -> 1374 | P37: 474488 | Q37: 285936 | R37: 288008 | S37: 304584 | T37: 213416 | U37: 308728 | V37: 362600 | W37: 196840 | X37: 70448 | Y37: 111888 | Z37: 41440 | AA37: 188552 | AB37: =IF(B37="","",SUM(P37:AA37)) -> 2846928
A38: 32 | B38: PK05000006282 | C38: 435 | D38: 421 | E38: 440 | F38: 416 | G38: 291 | H38: 446 | I38: 478 | J38: 356 | K38: 286 | L38: 302 | M38: 250 | N38: 415 | O38: =IF(B38="","",SUM(C38:N38)) -> 4536 | P38: 901320 | Q38: 872312 | R38: 911680 | S38: 861952 | T38: 602952 | U38: 924112 | V38: 990416 | W38: 737632 | X38: 592592 | Y38: 625744 | Z38: 518000 | AA38: 859880 | AB38: =IF(B38="","",SUM(P38:AA38)) -> 9398592
A39: 33 | B39: PK05000006283 | C39: 74 | D39: 116 | E39: 74 | F39: 73 | G39: 65 | H39: 68 | I39: 67 | J39: 98 | K39: 64 | L39: 69 | M39: 76 | N39: 94 | O39: =IF(B39="","",SUM(C39:N39)) -> 938 | P39: 164724 | Q39: 258216 | R39: 164724 | S39: 162498 | T39: 144690 | U39: 151368 | V39: 149142 | W39: 218148 | X39: 142464 | Y39: 153594 | Z39: 169176 | AA39: 209244 | AB39: =IF(B39="","",SUM(P39:AA39)) -> 2087988
A40: 34 | B40: PK05000006284 | C40: 22 | D40: 27 | E40: 11 | F40: 20 | G40: 34 | H40: 42 | I40: 23 | J40: 20 | K40: 39 | L40: 16 | M40: 17 | N40: 17 | O40: =IF(B40="","",SUM(C40:N40)) -> 288 | P40: 48972 | Q40: 60102 | R40: 24486 | S40: 44520 | T40: 75684 | U40: 93492 | V40: 51198 | W40: 44520 | X40: 86814 | Y40: 35616 | Z40: 37842 | AA40: 37842 | AB40: =IF(B40="","",SUM(P40:AA40)) -> 641088
A41: 35 | B41: PK05000006286 | C41: 384 | D41: 659 | E41: 498 | F41: 465 | G41: 444 | H41: 648 | I41: 490 | J41: 534 | K41: 476 | L41: 519 | M41: 528 | N41: 527 | O41: =IF(B41="","",SUM(C41:N41)) -> 6172 | P41: 795648 | Q41: 1365448 | R41: 1031856 | S41: 963480 | T41: 919968 | U41: 1342656 | V41: 1015280 | W41: 1106448 | X41: 986272 | Y41: 1075368 | Z41: 1094016 | AA41: 1091944 | AB41: =IF(B41="","",SUM(P41:AA41)) -> 12788384
...
